<sdf version='1.6'>
  <world name='collision_world'>
    <model name='ground_plane'>
      <static>1</static>
      <link name='link'>
        <collision name='collision'>
          <geometry>
            <plane>
              <normal>0 0 1</normal>
              <size>100 100</size>
            </plane>
          </geometry>
          <surface>
            <friction>
              <ode>
                <mu>100</mu>
                <mu2>50</mu2>
              </ode>
              <torsional>
                <ode/>
              </torsional>
            </friction>
            <contact>
              <ode/>
            </contact>
            <bounce/>
          </surface>
          <max_contacts>10</max_contacts>
        </collision>
        <visual name='visual'>
          <cast_shadows>0</cast_shadows>
          <geometry>
            <plane>
              <normal>0 0 1</normal>
              <size>100 100</size>
            </plane>
          </geometry>
          <material>
            <script>
              <uri>file://media/materials/scripts/gazebo.material</uri>
              <name>Gazebo/Grey</name>
            </script>
          </material>
        </visual>
        <self_collide>0</self_collide>
        <kinematic>0</kinematic>
        <gravity>1</gravity>
      </link>
    </model>
    <light name='sun' type='directional'>
      <cast_shadows>1</cast_shadows>
      <pose frame=''>0 0 10 0 -0 0</pose>
      <diffuse>0.8 0.8 0.8 1</diffuse>
      <specular>0.1 0.1 0.1 1</specular>
      <attenuation>
        <range>1000</range>
        <constant>0.9</constant>
        <linear>0.01</linear>
        <quadratic>0.001</quadratic>
      </attenuation>
      <direction>-0.5 0.5 -1</direction>
    </light>
    <model name='collision_model'>
      <static>0</static>
      <link name='chassis'>
        <pose frame=''>0 0 0.25 0 -0 0</pose>
        <visual name='chassis_visual'>
          <pose frame=''>0 0 0 0 -0 0</pose>
          <geometry>
            <box>
              <size>1 0.5 0.2</size>
            </box>
          </geometry>
        </visual>
        <collision name='chassis_collision'>
          <pose frame=''>0 0 0 0 -0 0</pose>
          <geometry>
            <box>
              <size>1 0.5 0.2</size>
            </box>
          </geometry>
          <max_contacts>10</max_contacts>
          <surface>
            <contact>
              <ode/>
            </contact>
            <bounce/>
            <friction>
              <torsional>
                <ode/>
              </torsional>
              <ode/>
            </friction>
          </surface>
        </collision>
        <self_collide>0</self_collide>
        <inertial>
          <inertia>
            <ixx>1</ixx>
            <ixy>0</ixy>
            <ixz>0</ixz>
            <iyy>1</iyy>
            <iyz>0</iyz>
            <izz>1</izz>
          </inertia>
          <mass>1</mass>
        </inertial>
        <kinematic>0</kinematic>
        <gravity>1</gravity>
      </link>
      <link name='left_wheel'>
        <pose frame=''>0.25 0.325 0.175 -1.57089 0.141593 3.14159</pose>
        <visual name='left_wheel_visual'>
          <pose frame=''>0 0 0 0 -0 0</pose>
          <geometry>
            <cylinder>
              <radius>0.175</radius>
              <length>0.145</length>
            </cylinder>
          </geometry>
        </visual>
        <collision name='left_wheel_collision'>
          <pose frame=''>0 0 0 0 -0 0</pose>
          <geometry>
            <cylinder>
              <radius>0.175</radius>
              <length>0.145</length>
            </cylinder>
          </geometry>
          <max_contacts>10</max_contacts>
          <surface>
            <contact>
              <ode/>
            </contact>
            <bounce/>
            <friction>
              <torsional>
                <ode/>
              </torsional>
              <ode/>
            </friction>
          </surface>
        </collision>
        <self_collide>0</self_collide>
        <inertial>
          <inertia>
            <ixx>1</ixx>
            <ixy>0</ixy>
            <ixz>0</ixz>
            <iyy>1</iyy>
            <iyz>0</iyz>
            <izz>1</izz>
          </inertia>
          <mass>1</mass>
        </inertial>
        <kinematic>0</kinematic>
        <gravity>1</gravity>
      </link>
      <link name='right_wheel'>
        <pose frame=''>0.25 -0.325 0.175 1.5707 -0 0</pose>
        <visual name='right_wheel_visual'>
          <pose frame=''>0 0 0 0 -0 0</pose>
          <geometry>
            <cylinder>
              <radius>0.175</radius>
              <length>0.145</length>
            </cylinder>
          </geometry>
        </visual>
        <collision name='right_wheel_collision'>
          <pose frame=''>0 0 0 0 -0 0</pose>
          <geometry>
            <cylinder>
              <radius>0.175</radius>
              <length>0.145</length>
            </cylinder>
          </geometry>
          <max_contacts>10</max_contacts>
          <surface>
            <contact>
              <ode/>
            </contact>
            <bounce/>
            <friction>
              <torsional>
                <ode/>
              </torsional>
              <ode/>
            </friction>
          </surface>
        </collision>
        <self_collide>0</self_collide>
        <inertial>
          <inertia>
            <ixx>1</ixx>
            <ixy>0</ixy>
            <ixz>0</ixz>
            <iyy>1</iyy>
            <iyz>0</iyz>
            <izz>1</izz>
          </inertia>
          <mass>1</mass>
        </inertial>
        <kinematic>0</kinematic>
        <gravity>1</gravity>
      </link>
      <link name='central_wheel'>
        <pose frame=''>-0.25 0 0.175 0 -0 0</pose>
        <visual name='central_wheel_visual'>
          <pose frame=''>0 0 0 0 -0 0</pose>
          <geometry>
            <sphere>
              <radius>0.175</radius>
            </sphere>
          </geometry>
        </visual>
        <collision name='central_wheel_collision'>
          <pose frame=''>0 0 0 0 -0 0</pose>
          <geometry>
            <sphere>
              <radius>0.175</radius>
            </sphere>
          </geometry>
          <max_contacts>10</max_contacts>
          <surface>
            <contact>
              <ode/>
            </contact>
            <bounce/>
            <friction>
              <torsional>
                <ode/>
              </torsional>
              <ode/>
            </friction>
          </surface>
        </collision>
        <self_collide>0</self_collide>
        <inertial>
          <inertia>
            <ixx>1</ixx>
            <ixy>0</ixy>
            <ixz>0</ixz>
            <iyy>1</iyy>
            <iyz>0</iyz>
            <izz>1</izz>
          </inertia>
          <mass>1</mass>
        </inertial>
        <kinematic>0</kinematic>
        <gravity>1</gravity>
      </link>
      <model name='sensor_box'>
        <link name='sensor_link'>
          <pose frame=''>0.5 0 0.4 0 -0 0</pose>
          <collision name='sensor_box_collision'>
            <geometry>
              <box>
                <size>0.1 0.1 0.1</size>
              </box>
            </geometry>
            <max_contacts>10</max_contacts>
            <surface>
              <contact>
                <ode/>
              </contact>
              <bounce/>
              <friction>
                <torsional>
                  <ode/>
                </torsional>
                <ode/>
              </friction>
            </surface>
          </collision>
          <visual name='sensor_box_visual'>
            <geometry>
              <box>
                <size>0.1 0.1 0.1</size>
              </box>
            </geometry>
          </visual>
          <sensor name='my_contact' type='contact'>
            <contact>
              <collision>sensor_box_collision</collision>
              <topic>__default_topic__</topic>
            </contact>
          </sensor>
          <self_collide>0</self_collide>
          <inertial>
            <inertia>
              <ixx>1</ixx>
              <ixy>0</ixy>
              <ixz>0</ixz>
              <iyy>1</iyy>
              <iyz>0</iyz>
              <izz>1</izz>
            </inertia>
            <mass>1</mass>
          </inertial>
          <kinematic>0</kinematic>
          <gravity>1</gravity>
        </link>
      </model>
      <joint name='left_wheel_hinge' type='revolute'>
        <pose frame=''>0 0 0 0 -0 0</pose>
        <child>left_wheel</child>
        <parent>chassis</parent>
        <axis>
          <xyz>0 0 1</xyz>
          <use_parent_model_frame>0</use_parent_model_frame>
          <limit>
            <lower>-1e+16</lower>
            <upper>1e+16</upper>
          </limit>
          <dynamics>
            <spring_reference>0</spring_reference>
            <spring_stiffness>0</spring_stiffness>
          </dynamics>
        </axis>
      </joint>
      <joint name='right_wheel_hinge' type='revolute'>
        <pose frame=''>0 0 0 0 -0 0</pose>
        <child>right_wheel</child>
        <parent>chassis</parent>
        <axis>
          <xyz>0 0 1</xyz>
          <use_parent_model_frame>0</use_parent_model_frame>
          <limit>
            <lower>-1e+16</lower>
            <upper>1e+16</upper>
          </limit>
          <dynamics>
            <spring_reference>0</spring_reference>
            <spring_stiffness>0</spring_stiffness>
          </dynamics>
        </axis>
      </joint>
      <joint name='central_wheel_hinge' type='ball'>
        <pose frame=''>0 0 0 0 -0 0</pose>
        <child>central_wheel</child>
        <parent>chassis</parent>
      </joint>
      <joint name='collision_sensor_joint' type='fixed'>
        <pose frame=''>0 0 0 0 -0 0</pose>
        <child>sensor_box::sensor_link</child>
        <parent>chassis</parent>
      </joint>
      <plugin name='carPlugin' filename='libcarPlugin.so'/>
      <plugin name='postbox1Plugin' filename='libpostbox1Plugin.so'/>
      <plugin name='postbox2Plugin' filename='libpostbox2Plugin.so'/>
    </model>
    <gravity>0 0 -9.8</gravity>
    <magnetic_field>6e-06 2.3e-05 -4.2e-05</magnetic_field>
    <atmosphere type='adiabatic'/>
    <physics name='default_physics' default='0' type='ode'>
      <max_step_size>0.001</max_step_size>
      <real_time_factor>1</real_time_factor>
      <real_time_update_rate>1000</real_time_update_rate>
    </physics>
    <scene>
      <ambient>0.4 0.4 0.4 1</ambient>
      <background>0.7 0.7 0.7 1</background>
      <shadows>1</shadows>
    </scene>
    <spherical_coordinates>
      <surface_model>EARTH_WGS84</surface_model>
      <latitude_deg>0</latitude_deg>
      <longitude_deg>0</longitude_deg>
      <elevation>0</elevation>
      <heading_deg>0</heading_deg>
    </spherical_coordinates>
    <model name='postbox1'>
      <model name='postbox'>
        <static>1</static>
        <link name='link'>
          <collision name='collision'>
            <geometry>
              <mesh>
                <uri>model://postbox/meshes/postbox.dae</uri>
              </mesh>
            </geometry>
            <max_contacts>10</max_contacts>
            <surface>
              <contact>
                <ode/>
              </contact>
              <bounce/>
              <friction>
                <torsional>
                  <ode/>
                </torsional>
                <ode/>
              </friction>
            </surface>
          </collision>
          <visual name='visual'>
            <geometry>
              <mesh>
                <uri>model://postbox/meshes/postbox.dae</uri>
              </mesh>
            </geometry>
          </visual>
          <self_collide>0</self_collide>
          <kinematic>0</kinematic>
          <gravity>1</gravity>
        </link>
        <pose frame=''>0 0 0 0 -0 0</pose>
      </model>
      <static>0</static>
      <allow_auto_disable>1</allow_auto_disable>
      <pose frame=''>-4 -2 0 0 -0 0</pose>
    </model>
    <state world_name='collision_world'>
      <sim_time>107 324000000</sim_time>
      <real_time>89 559252232</real_time>
      <wall_time>1599006319 290504627</wall_time>
      <iterations>89304</iterations>
      <model name='collision_model'>
        <pose frame=''>-7.8e-05 9.1e-05 3e-06 0 -1.3e-05 -6.3e-05</pose>
        <scale>1 1 1</scale>
        <link name='central_wheel'>
          <pose frame=''>-0.25008 0.000107 0.175 3.05776 -1.23209 -3.06497</pose>
          <velocity>5e-06 -3e-06 8e-06 1.3e-05 2.7e-05 0</velocity>
          <acceleration>0.000983 -0.019538 0.015589 0.097535 0.006383 0</acceleration>
          <wrench>0.000983 -0.019538 0.015589 0 -0 0</wrench>
        </link>
        <link name='chassis'>
          <pose frame=''>-8.1e-05 9.1e-05 0.250003 0 -1.3e-05 -6.3e-05</pose>
          <velocity>-1e-06 -0.000215 -1.7e-05 0.001099 -1.3e-05 -3.2e-05</velocity>
          <acceleration>-0.011178 -0.438817 -0.034667 2.19744 -0.026317 -0.052521</acceleration>
          <wrench>-0.011178 -0.438817 -0.034667 0 -0 0</wrench>
        </link>
        <link name='left_wheel'>
          <pose frame=''>0.24994 0.325075 0.175007 -1.57092 -0.671158 -3.14157</pose>
          <velocity>2e-06 -0.000189 0.000353 0.00109 -3e-06 -3.4e-05</velocity>
          <acceleration>-0.007889 -0.385573 0.706219 2.1806 0.000172 -0.056782</acceleration>
          <wrench>-0.007889 -0.385573 0.706219 0 -0 0</wrench>
        </link>
        <link name='right_wheel'>
          <pose frame=''>0.249899 -0.324924 0.175007 1.57065 0.847217 -0.000172</pose>
          <velocity>4e-06 -0.000182 -0.000409 0.001089 -5e-06 -3.5e-05</velocity>
          <acceleration>0.002627 -0.371186 -0.818272 2.17896 0.000136 -0.057734</acceleration>
          <wrench>0.002627 -0.371186 -0.818272 0 -0 0</wrench>
        </link>
        <model name='sensor_box'>
          <pose frame=''>4.21356 -0.017259 -0.00012 2e-06 2.6e-05 -0.010306</pose>
          <scale>1 1 1</scale>
          <link name='sensor_link'>
            <pose frame=''>0.499917 6e-05 0.40001 0 -1.3e-05 -6.3e-05</pose>
            <velocity>-6e-06 -0.000387 -4e-06 0.001096 -2e-05 -2.6e-05</velocity>
            <acceleration>-0.021183 -0.776893 -0.008934 2.19229 -0.040392 -0.040302</acceleration>
            <wrench>-0.021183 -0.776893 -0.008934 0 -0 0</wrench>
          </link>
        </model>
      </model>
      <model name='ground_plane'>
        <pose frame=''>0 0 0 0 -0 0</pose>
        <scale>1 1 1</scale>
        <link name='link'>
          <pose frame=''>0 0 0 0 -0 0</pose>
          <velocity>0 0 0 0 -0 0</velocity>
          <acceleration>0 0 0 0 -0 0</acceleration>
          <wrench>0 0 0 0 -0 0</wrench>
        </link>
      </model>
      <model name='postbox1'>
        <pose frame=''>-4 -2 0 0 -0 0</pose>
        <scale>1 1 1</scale>
        <model name='postbox'>
          <pose frame=''>-4 -2 0 0 -0 0</pose>
          <scale>1 1 1</scale>
          <link name='link'>
            <pose frame=''>-4 -2 0 0 -0 0</pose>
            <velocity>0 0 0 0 -0 0</velocity>
            <acceleration>0 0 0 0 -0 0</acceleration>
            <wrench>0 0 0 0 -0 0</wrench>
          </link>
        </model>
      </model>
      <model name='postbox2'>
        <pose frame=''>-8 -2 0 0 -0 0</pose>
        <scale>1 1 1</scale>
        <model name='postbox'>
          <pose frame=''>-8 -2 0 0 -0 0</pose>
          <scale>1 1 1</scale>
          <link name='link'>
            <pose frame=''>-8 -2 0 0 -0 0</pose>
            <velocity>0 0 0 0 -0 0</velocity>
            <acceleration>0 0 0 0 -0 0</acceleration>
            <wrench>0 0 0 0 -0 0</wrench>
          </link>
        </model>
      </model>
      <light name='sun'>
        <pose frame=''>0 0 10 0 -0 0</pose>
      </light>
    </state>
    <gui fullscreen='0'>
      <camera name='user_camera'>
        <pose frame=''>-4.10409 11.4359 7.00548 -0 0.539643 -1.675</pose>
        <view_controller>orbit</view_controller>
        <projection_type>perspective</projection_type>
      </camera>
    </gui>
    <model name='postbox2'>
      <model name='postbox'>
        <static>1</static>
        <link name='link'>
          <collision name='collision'>
            <geometry>
              <mesh>
                <uri>model://postbox/meshes/postbox.dae</uri>
              </mesh>
            </geometry>
            <max_contacts>10</max_contacts>
            <surface>
              <contact>
                <ode/>
              </contact>
              <bounce/>
              <friction>
                <torsional>
                  <ode/>
                </torsional>
                <ode/>
              </friction>
            </surface>
          </collision>
          <visual name='visual'>
            <geometry>
              <mesh>
                <uri>model://postbox/meshes/postbox.dae</uri>
              </mesh>
            </geometry>
          </visual>
          <self_collide>0</self_collide>
          <kinematic>0</kinematic>
          <gravity>1</gravity>
        </link>
        <pose frame=''>0 0 0 0 -0 0</pose>
      </model>
      <static>0</static>
      <allow_auto_disable>1</allow_auto_disable>
      <pose frame=''>-8 -2 0 0 -0 0</pose>
    </model>
  </world>
</sdf>
