<?xml version="1.0"?>
<sdf version="1.6">
    <world name="collision_world">

        <include>
            <uri>model://ground_plane</uri>
        </include>

        <include>
            <uri>model://sun</uri>
        </include>

        <model name='collision_model'>
        <static>false</static>
            <link name='chassis'>
                <pose>0 0 .25 0 0 0</pose>

                <visual name='chassis_visual'>
                    <pose>0 0 0 0 -0 0</pose>
                    <geometry>
                        <box>
                            <size>1 0.5 0.2</size>
                        </box>
                    </geometry>
                </visual>

                <collision name='chassis_collision'>
                    <pose>0 0 0 0 -0 0</pose>
                    <geometry>
                        <box>
                            <size>1 0.5 0.2</size>
                        </box>
                    </geometry>
                </collision>
            </link>

            <link name='left_wheel'>
                <pose>0.325 0.325 0.175 1.5707 0 0</pose>

                <visual name='left_wheel_visual'>
                    <pose>0 0 0 0 -0 0</pose>
                    <geometry>
                        <cylinder>
                            <radius>0.175</radius>
                            <length>0.145</length>
                        </cylinder>
                    </geometry>
                </visual>

                <collision name='left_wheel_collision'>
                    <pose>0 0 0 0 -0 0</pose>
                    <geometry>
                        <cylinder>
                            <radius>0.175</radius>
                            <length>0.145</length>
                        </cylinder>
                    </geometry>
                </collision>
            </link>

            <link name='right_wheel'>
                <pose>0.325 -0.325 0.175 1.5707 0 0</pose>

                <visual name='right_wheel_visual'>
                    <pose>0 0 0 0 -0 0</pose>
                    <geometry>
                        <cylinder>
                            <radius>0.175</radius>
                            <length>0.145</length>
                        </cylinder>
                    </geometry>
                </visual>

                <collision name='right_wheel_collision'>
                    <pose>0 0 0 0 -0 0</pose>
                    <geometry>
                        <cylinder>
                            <radius>0.175</radius>
                            <length>0.145</length>
                        </cylinder>
                    </geometry>
                </collision>
            </link>

            <link name='second_left_wheel'>
                <pose>-0.325 0.325 0.175 1.5707 0 0</pose>

                <visual name='second_left_wheel_visual'>
                    <pose>0 0 0 0 -0 0</pose>
                    <geometry>
                        <cylinder>
                            <radius>0.175</radius>
                            <length>0.145</length>
                        </cylinder>
                    </geometry>
                </visual>

                <collision name='second_left_wheel_collision'>
                    <pose>0 0 0 0 -0 0</pose>
                    <geometry>
                        <cylinder>
                            <radius>0.175</radius>
                            <length>0.145</length>
                        </cylinder>
                    </geometry>
                </collision>
            </link>

            <link name='second_right_wheel'>
                <pose>-0.325 -0.325 0.175 1.5707 0 0</pose>

                <visual name='second_right_wheel_visual'>
                    <pose>0 0 0 0 -0 0</pose>
                    <geometry>
                        <cylinder>
                            <radius>0.175</radius>
                            <length>0.145</length>
                        </cylinder>
                    </geometry>
                </visual>

                <collision name='second_right_wheel_collision'>
                    <pose>0 0 0 0 -0 0</pose>
                    <geometry>
                        <cylinder>
                            <radius>0.175</radius>
                            <length>0.145</length>
                        </cylinder>
                    </geometry>
                </collision>
            </link>

            <!--<link name='central_wheel'>
                <pose>-0.25 0 0.175 0 0 0</pose>

                <visual name='central_wheel_visual'>
                    <pose>0 0 0 0 -0 0</pose>
                    <geometry>
                        <sphere>
                            <radius>0.175</radius>
                        </sphere>
                    </geometry>
                </visual>

                <collision name='central_wheel_collision'>
                    <pose>0 0 0 0 -0 0</pose>
                    <geometry>
                        <sphere>
                            <radius>0.175</radius>
                        </sphere>
                    </geometry>
                </collision>
            </link>-->

           <!-- <model name='collision_sensor'>
                <link name='collision_sensor_link'>
                    <pose>0.5 0 0.4 0 -0 0</pose>
                    <visual name='collision_snesor_visual'>
                        <geometry>
                            <box>
                                <size>0.1 0.1 0.1</size>
                            </box>
                        </geometry>
                    </visual>
                    <collision name='collision_sensor_collision'>
                        <geometry>
                            <box>
                                <size>0.1 0.1 0.1</size>
                            </box>
                        </geometry>
                    </collision>
                    <sensor name='my_contact' type='contact'>
                        
                       <plugin name='collision_sensor' filename='libmyCollisionPlugin.so'/>
                       
                        <contact>
                            <collision>collision_sensor_collision</collision>
                        </contact>
                    </sensor>
                </link>
            </model>-->

            <model name='sensor_box'>
                <link name='sensor_link'>
                    <pose>0.5 0 0.4 0 -0 0</pose>

                    <collision name="sensor_box_collision">
                        <geometry>
                        <box>
                            <size>0.1 0.1 0.1</size>
                        </box>
                        </geometry>
                    </collision>

                    <visual name="sensor_box_visual">
                        <geometry>
                        <box>
                            <size>0.1 0.1 0.1</size>
                        </box>
                        </geometry>
                    </visual>

                    <sensor name='my_contact' type='contact'>
                        <plugin name="myCollisionSensorPlugin" filename="libmyCollisionSensorPlugin.so"/>
                        <contact>
                        <collision>sensor_box_collision</collision>
                        </contact>
                    </sensor>
                </link>
            </model>

            <joint type='revolute' name='left_wheel_hinge'>
                <pose>0 0 0 0 0 0</pose>
                <child>left_wheel</child>
                <parent>chassis</parent>
                <axis>
                    <xyz>0 0 1</xyz>
                </axis>
            </joint>

            <joint type='revolute' name='right_wheel_hinge'>
                <pose>0 0 0 0 0 0</pose>
                <child>right_wheel</child>
                <parent>chassis</parent>
                <axis>
                    <xyz>0 0 1</xyz>
                </axis>
            </joint>

            <joint type='revolute' name='second_left_wheel_hinge'>
                <pose>0 0 0 0 0 0</pose>
                <child>second_left_wheel</child>
                <parent>chassis</parent>
                <axis>
                    <xyz>0 0 1</xyz>
                </axis>
            </joint>

            <joint type='revolute' name='second_right_wheel_hinge'>
                <pose>0 0 0 0 0 0</pose>
                <child>second_right_wheel</child>
                <parent>chassis</parent>
                <axis>
                    <xyz>0 0 1</xyz>
                </axis>
            </joint>-

            <!--<joint type='ball' name='central_wheel_hinge'>
                <pose>0 0 0 0 0 0</pose>
                <child>central_wheel</child>
                <parent>chassis</parent>
            </joint>-->

            <joint type='fixed' name='collision_sensor_joint'>
                <pose>0 0 0 0 0 0</pose>
                <child>sensor_box::sensor_link</child>
                <parent>chassis</parent>
            </joint>

            <plugin name="myCollisionModelPlugin" filename="libmyCollisionModelPlugin.so"/>
        </model>



        <model name="box">
            <static>true</static>
            <link name="link">
                <pose>6 0 0.5 0 0 0</pose>
                <collision name="box_collision">
                <geometry>
                    <box>
                    <size>1 1 1</size>
                    </box>
                </geometry>
                </collision>
                <visual name="visual">
                <geometry>
                    <box>
                    <size>1 1 1</size>
                    </box>
                </geometry>
                </visual>
            </link>
        </model>
    </world>
</sdf>
